Workbook

Sheet はじめに
A1: ProofLoop 投資回収モデル（2026-08 〜 2027-01）
A4: 【目的】学生インターン3名の人件費を、2027年1月末までに回収できるラインを逆算する。
A6: 【使い方】編集するのは「前提」シートの黄色いセルだけ。他はすべて数式で自動計算される。
A8: ════════ 回収すべき金額 ════════
A9: 月次コスト ¥160,880（人件費 3名×¥2,000×6h/週×4.33週 ＝ ¥155,880 ＋ 固定費 ¥5,000）
A10: 累計コスト ¥965,280（6ヶ月）
A11: 回収は2つの定義で判定する。A＝累計売上≧累計コスト。B＝1月単月の売上≧月次コスト（＝以後自走）。
A13: ════════ 団体獲得のモデルを 2026-08-07 に組み替えた ════════
A14: 当初は「コールドな新規開拓で500通」としていたが、これは最大の資産を勘定に入れていなかった。
A15: 本番DBを実査した結果：
A16: ・承認済み掲載団体 2,421件のうち、アカウントの主がいるのは わずか1件
A17: ・SNS または公式サイトで到達できるのは 2,354件（97.2%）
... A61: 3. 歩留まりはすべて仮定。8月の第1バッチ（通知200件）が claim率の初回実測を出す。9月頭に引き直すこと。

Sheet 前提
A1: 前提（黄色いセルだけを編集してください）
A3: ■ コスト前提
A4: インターン人数 | B4: 3 | C4: 名
A5: 時給 | B5: 2000 | C5: 円
A6: 1人あたり週稼働時間 | B6: 6 | C6: 時間/週
A7: 週数/月 | B7: 4.33 | C7: 週
A8: 月次人件費 | B8: =B4*B5*B6*B7
A9: その他固定費（ツール等） | B9: 5000
A10: 月次コスト合計 | B10: =B8+B9
A11: 対象期間（ヶ月） | B11: 6
A12: 累計コスト＝回収すべき金額 | B12: =B10*B11
A14: ■ 収益単価の前提
A15: 協賛1案件の平均金額 | B15: 500000 | H15: ★最大の急所。未検証の仮置き
A16: ProofLoop 手数料率 | B16: 0.2
A17: 1案件あたり ProofLoop 収益 | B17: =B15*B16
A18: 団体課金 月額 | B18: 3000 | C18: 円/団体/月
A19: 有料化率（実運用団体のうち） | B19: 0.2
A20: 課金開始月（1=8月 … 6=1月） | B20: 4 | C20: 4 ＝ 2026-11
A21: その他収益（アフィリエイト等） | B21: 0 | C21: 円/月
A23: ■ 団体レーン（掲載通知＝ページの claim 誘導）
A24: 到達可能な掲載団体数 | B24: 2354 | H24: 本番DB実査（2026-08-07）。承認済2,421のうちSNS/サイト到達可
A25: 掲載通知 → 登録（claim）率 | B25: 0.08 | H25: 未検証。8月の第1バッチで初回実測が出る
A26: ネットワーク効果係数（月次） | B26: 0.03 | H26: 登録団体1つが1ヶ月に呼ぶ新規登録数（口コミ・学生経由）
A27: 登録 → 実運用率 | B27: 0.2 | H27: 実運用＝財務DXに実データを入れている状態
A28: 実運用団体の月次継続率 | B28: 0.92
A30: ■ 企業レーン
A31: 打診→反応率 | B31: 0.1
A32: 反応→商談率 | B32: 0.6
A33: 商談→成約率 | B33: 0.4
A34: 1案件に必要な実運用団体数 | B34: 1 | H34: 供給側の制約。団体が足りなければ案件は成立しない
A36: ■ 回収目標
A37: 目標回収率（累計） | B37: 1 | H37: 100%＝1月末に投資を全額回収
A39: ■ 月別の投下量（＝実行計画そのもの）
A40: 月 | B40: 2026-08 | C40: 2026-09 | D40: 2026-10 | E40: 2026-11 | F40: 2026-12 | G40: 2027-01
A41: 掲載通知 接触数（件） | B41: 200 | C41: 350 | D41: 350 | E41: 250 | F41: 150 | G41: 100 | H41: ="合計 "&SUM(B41:G41)&"件 / "&SUM(B42:G42)&"社"
A42: 企業打診数（社） | B42: 0 | C42: 60 | D42: 110 | E42: 110 | F42: 80 | G42: 70
A44: ■ 1件あたり所要時間（稼働キャパの計算に使う）
A45: 掲載通知1件（SNS DM・サイトフォーム） | B45: 0.04 | H45: ＝2.4分。一斉自動送信はできない
A46: 登録団体1件のセルフサーブ支援 | B46: 0.2 | H46: 問い合わせ対応のみ
A47: 実運用化のハンズオン1団体 | B47: 1.5 | H47: ★3.0hだと稼働が破綻する。セルフサーブ化が前提
...

Sheet 1月末KPI目標
A1: 2027年1月末に到達すべきKPI
A3: B列＝いまの前提で到達する見込み ／ C列＝投資を回収するために必要な水準 ／ D列＝差
A4: ※ 登録団体数は「回収に必要な水準」が低く出る（案件の律速が企業側のため）。100団体は回収ではなくネットワーク効果を狙う目標である。
A6: ■ KPI一覧
A7: KPI | B7: 見込み | C7: 必要水準 | D7: 差 | E7: 必要水準の出し方
A8: 累計 掲載通知 接触数（件） | B8: =月次モデル!H13 | C8: =逆算とギャップ!$B$21*前提!$B$34/前提!$B$27/前提!$B$25 | D8: =B8-C8 | E8: 必要実運用 ÷ 実運用化率 ÷ claim率（ネットワーク効果は無視＝保守側）
A9: 累計 登録団体数 ★ | B9: =月次モデル!G18 | C9: =逆算とギャップ!$B$21*前提!$B$34/前提!$B$27 | D9: =B9-C9 | E9: 必要実運用 ÷ 登録→実運用率
A10: 実運用団体数（1月末） | B10: =月次モデル!G20 | C10: =逆算とギャップ!$B$21*前提!$B$34 | D10: =B10-C10 | E10: 必要案件数 × 1案件に必要な団体数（供給の下限）
A11: 累計 企業打診数（社） | B11: =月次モデル!H23 | C11: =逆算とギャップ!$B$21/(前提!$B$31*前提!$B$32*前提!$B$33) | D11: =B11-C11 | E11: 必要案件数 ÷（反応率×商談率×成約率）
A12: 累計 商談数 | B12: =月次モデル!H25 | C12: =逆算とギャップ!$B$21/前提!$B$33 | D12: =B12-C12 | E12: 必要案件数 ÷ 商談→成約率
A13: 累計 成立案件数 | B13: =月次モデル!G29 | C13: =逆算とギャップ!$B$21 | D13: =B13-C13 | E13: 協賛で稼ぐ必要額 ÷ 1案件あたり収益
A14: 1月単月の成立案件数 | B14: =月次モデル!G28 | C14: =逆算とギャップ!$B$14 | D14: =B14-C14 | E14: 単月黒字に必要な月次案件数
A15: 累計売上 | B15: =月次モデル!G36 | C15: =逆算とギャップ!$B$4 | D15: =B15-C15 | E15: ＝累計コスト×目標回収率
A16: 1月単月 売上 | B16: =月次モデル!G35 | C16: =前提!$B$10 | D16: =B16-C16 | E16: ＝1ヶ月ぶんのコスト
A17: 累計回収率 | B17: =逆算とギャップ!$B$7 | C17: =前提!$B$37 | D17: =B17-C17 | E17: 目標値
A18: 整合チェック：累計案件数 ÷ 累計登録団体数 | B18: =IF(月次モデル!G18=0,0,月次モデル!G29/月次モデル!G18) | E18: 1を超えたら「1団体が半年で2件以上の協賛を取る」前提。要見直し
A20: ■ 必要水準を実行できるのか（稼働の突き合わせ）
A21: 必要水準を実行するのに要る工数 | B21: =C8*前提!$B$45+C9*前提!$B$46+C10*前提!$B$47+C11*前提!$B$48+C12*前提!$B$49
A22: アウトリーチに充てられる時間（6ヶ月） | B22: =稼働キャパ!$B$6
A23: 消化率 | B23: =IF(B22=0,0,B21/B22)
A24: 判定 | B24: =IF(B23<=1,"実行可能","実行不能") | C24: =IF(B23<=1,"週"&前提!$B$6&"時間×"&前提!$B$4&"名の枠に収まる","枠を "&TEXT(B23-1,"0%")&" 超過。単価を上げるか人員を増やすしかない")
A26: ※ C列（必要水準）に届かないなら、選べる道は4つ：①投下量を増やす ②協賛単価を上げる ③手数料率を上げる ④回収の定義をAからBに変える。
A27: 必要水準は「逆算とギャップ」シートの①〜④に出ている。
A28: ※ 検証済み：協賛単価¥300,000だと必要水準の消化率が147%になり、投下量をどれだけ積んでも物理的に実行できない。

Sheet 月次モデル
A1: 月次モデル（すべて「前提」シートから自動計算）
A3: 月 | B3: =前提!B40 | C3: =前提!C40 | D3: =前提!D40 | E3: =前提!E40 | F3: =前提!F40 | G3: =前提!G40 | H3: 合計/最終
A4: 月インデックス | B4: 1 | C4: 2 | D4: 3 | E4: 4 | F4: 5 | G4: 6
A6: ■ コスト
A7: 人件費 | B7: =前提!$B$8 | C7: =前提!$B$8 | D7: =前提!$B$8 | E7: =前提!$B$8 | F7: =前提!$B$8 | G7: =前提!$B$8 | H7: =SUM(B7:G7)
A8: その他固定費 | B8: =前提!$B$9 | C8: =前提!$B$9 | D8: =前提!$B$9 | E8: =前提!$B$9 | F8: =前提!$B$9 | G8: =前提!$B$9 | H8: =SUM(B8:G8)
A9: 月次コスト合計 | B9: =B7+B8 | C9: =C7+C8 | D9: =D7+D8 | E9: =E7+E8 | F9: =F7+F8 | G9: =G7+G8 | H9: =SUM(B9:G9)
A10: 累計コスト | B10: =SUM($B$9:B9) | C10: =SUM($B$9:C9) | D10: =SUM($B$9:D9) | E10: =SUM($B$9:E9) | F10: =SUM($B$9:F9) | G10: =SUM($B$9:G9) | H10: =G10
A12: ■ 団体レーン（掲載通知＝claim誘導）
A13: 掲載通知 接触数（件） | B13: =MIN(前提!B41,前提!$B$24) | C13: =MIN(前提!C41,MAX(0,前提!$B$24-B14)) | D13: =MIN(前提!D41,MAX(0,前提!$B$24-C14)) | E13: =MIN(前提!E41,MAX(0,前提!$B$24-D14)) | F13: =MIN(前提!F41,MAX(0,前提!$B$24-E14)) | G13: =MIN(前提!G41,MAX(0,前提!$B$24-F14)) | H13: =SUM(B13:G13)
A14: 累計 接触数 | B14: =SUM($B$13:B13) | C14: =SUM($B$13:C13) | D14: =SUM($B$13:D13) | E14: =SUM($B$13:E13) | F14: =SUM($B$13:F13) | G14: =SUM($B$13:G13) | H14: =G14
A15: 新規登録（通知経由） | B15: =B13*前提!$B$25 | C15: =C13*前提!$B$25 | D15: =D13*前提!$B$25 | E15: =E13*前提!$B$25 | F15: =F13*前提!$B$25 | G15: =G13*前提!$B$25 | H15: =SUM(B15:G15)
A16: 新規登録（ネットワーク経由） | B16: =0 | C16: =B18*前提!$B$26 | D16: =C18*前提!$B$26 | E16: =D18*前提!$B$26 | F16: =E18*前提!$B$26 | G16: =F18*前提!$B$26 | H16: =SUM(B16:G16)
A17: 新規登録 合計 | B17: =B15+B16 | C17: =C15+C16 | D17: =D15+D16 | E17: =E15+E16 | F17: =F15+F16 | G17: =G15+G16 | H17: =SUM(B17:G17)
A18: 累計 登録団体 ★ | B18: =B17 | C18: =B18+C17 | D18: =C18+D17 | E18: =D18+E17 | F18: =E18+F17 | G18: =F18+G17 | H18: =G18
A19: 新規 実運用団体 | B19: =B17*前提!$B$27 | C19: =C17*前提!$B$27 | D19: =D17*前提!$B$27 | E19: =E17*前提!$B$27 | F19: =F17*前提!$B$27 | G19: =G17*前提!$B$27 | H19: =SUM(B19:G19)
A20: 実運用団体（月末・継続率考慮） | B20: =B19 | C20: =B20*前提!$B$28+C19 | D20: =C20*前提!$B$28+D19 | E20: =D20*前提!$B$28+E19 | F20: =E20*前提!$B$28+F19 | G20: =F20*前提!$B$28+G19 | H20: =G20
A22: ■ 企業レーン
A23: 企業打診数（社） | B23: =前提!B42 | C23: =前提!C42 | D23: =前提!D42 | E23: =前提!E42 | F23: =前提!F42 | G23: =前提!G42 | H23: =SUM(B23:G23)
A24: 反応 | B24: =B23*前提!$B$31 | C24: =C23*前提!$B$31 | D24: =D23*前提!$B$31 | E24: =E23*前提!$B$31 | F24: =F23*前提!$B$31 | G24: =G23*前提!$B$31 | H24: =SUM(B24:G24)
A25: 商談 | B25: =B24*前提!$B$32 | C25: =C24*前提!$B$32 | D25: =D24*前提!$B$32 | E25: =E24*前提!$B$32 | F25: =F24*前提!$B$32 | G25: =G24*前提!$B$32 | H25: =SUM(B25:G25)
A26: 成約見込（需要側） | B26: =B25*前提!$B$33 | C26: =C25*前提!$B$33 | D26: =D25*前提!$B$33 | E26: =E25*前提!$B$33 | F26: =F25*前提!$B$33 | G26: =G25*前提!$B$33 | H26: =SUM(B26:G26)
A27: 供給上限（実運用団体の制約） | B27: =B20/前提!$B$34 | C27: =C20/前提!$B$34 | D27: =D20/前提!$B$34 | E27: =E20/前提!$B$34 | F27: =F20/前提!$B$34 | G27: =G20/前提!$B$34 | H27: —
A28: 成立案件数 | B28: =MIN(B26,B27) | C28: =MIN(C26,C27) | D28: =MIN(D26,D27) | E28: =MIN(E26,E27) | F28: =MIN(F26,F27) | G28: =MIN(G26,G27) | H28: =SUM(B28:G28)
A29: 累計 案件数 | B29: =SUM($B$28:B28) | C29: =SUM($B$28:C28) | D29: =SUM($B$28:D28) | E29: =SUM($B$28:E28) | F29: =SUM($B$28:F28) | G29: =SUM($B$28:G28) | H29: =G29
A31: ■ 収益
A32: 協賛手数料 | B32: =B28*前提!$B$17 | C32: =C28*前提!$B$17 | D32: =D28*前提!$B$17 | E32: =E28*前提!$B$17 | F32: =F28*前提!$B$17 | G32: =G28*前提!$B$17 | H32: =SUM(B32:G32)
A33: 団体課金 | B33: =IF(B$4>=前提!$B$20,B20*前提!$B$19*前提!$B$18,0) | C33: =IF(C$4>=前提!$B$20,C20*前提!$B$19*前提!$B$18,0) | D33: =IF(D$4>=前提!$B$20,D20*前提!$B$19*前提!$B$18,0) | E33: =IF(E$4>=前提!$B$20,E20*前提!$B$19*前提!$B$18,0) | F33: =IF(F$4>=前提!$B$20,F20*前提!$B$19*前提!$B$18,0) | G33: =IF(G$4>=前提!$B$20,G20*前提!$B$19*前提!$B$18,0) | H33: =SUM(B33:G33)
A34: その他収益 | B34: =前提!$B$21 | C34: =前提!$B$21 | D34: =前提!$B$21 | E34: =前提!$B$21 | F34: =前提!$B$21 | G34: =前提!$B$21 | H34: =SUM(B34:G34)
A35: 月次売上合計 | B35: =SUM(B32:B34) | C35: =SUM(C32:C34) | D35: =SUM(D32:D34) | E35: =SUM(E32:E34) | F35: =SUM(F32:F34) | G35: =SUM(G32:G34) | H35: =SUM(B35:G35)
A36: 累計売上 | B36: =SUM($B$35:B35) | C36: =SUM($B$35:C35) | D36: =SUM($B$35:D35) | E36: =SUM($B$35:E35) | F36: =SUM($B$35:F35) | G36: =SUM($B$35:G35) | H36: =G36
A38: ■ 回収
A39: 月次収支 | B39: =B35-B9 | C39: =C35-C9 | D39: =D35-D9 | E39: =E35-E9 | F39: =F35-F9 | G39: =G35-G9 | H39: =G40
A40: 累計収支 | B40: =B36-B10 | C40: =C36-C10 | D40: =D36-D10 | E40: =E36-E10 | F40: =F36-F10 | G40: =G36-G10 | H40: =G40
A41: 累計回収率 | B41: =IF(B10=0,0,B36/B10) | C41: =IF(C10=0,0,C36/C10) | D41: =IF(D10=0,0,D36/D10) | E41: =IF(E10=0,0,E36/E10) | F41: =IF(F10=0,0,F36/F10) | G41: =IF(G10=0,0,G36/G10) | H41: =G41
A42: 月次で黒字か | B42: =IF(B39>=0,"黒字","赤字") | C42: =IF(C39>=0,"黒字","赤字") | D42: =IF(D39>=0,"黒字","赤字") | E42: =IF(E39>=0,"黒字","赤字") | F42: =IF(F39>=0,"黒字","赤字") | G42: =IF(G39>=0,"黒字","赤字") | H42: =IF(G39>=0,"黒字","赤字")
A44: ※ 13行目は到達可能な掲載団体数（前提 B24＝2,354）を上限として打ち止まる。
A45: ※ 27行目「供給上限」は、実運用団体が足りないと案件が成立しないという制約。28行目は需要と供給の少ない方。
A46: 全期間で需要（企業側）が下回る＝案件の律速は企業側。団体を増やしても案件数は増えない。

Sheet 逆算とギャップ
A1: 逆算とギャップ（回収に必要な水準 vs いまの見込み）
A3: ■ 定義A：累計回収（1月末までの累計売上 ≧ 累計コスト）
A4: 必要累計売上 | B4: =前提!$B$12*前提!$B$37 | C4: 回収すべき金額
A5: 見込み累計売上 | B5: =月次モデル!G36 | C5: いまの前提で到達する売上
A6: ギャップ（不足額） | B6: =B4-B5 | C6: プラスなら足りていない
A7: 累計回収率 | B7: =IF(B4=0,0,B5/B4) | C7: 100%で回収達成
A9: ■ 定義B：月次ランレート黒字（1月単月の売上 ≧ 1ヶ月ぶんのコスト）
A10: 必要月次売上 | B10: =前提!$B$10 | C10: 1ヶ月ぶんのコスト
A11: 1月の見込み売上 | B11: =月次モデル!G35
A12: ギャップ（不足額） | B12: =B10-B11
A13: 達成率 | B13: =IF(B10=0,0,B11/B10) | C13: 100%で単月黒字
A14: 1月に必要な成立案件数（協賛のみで賄う場合） | B14: =B10/前提!$B$17 | C14: 月あたり
A16: ■ 定義Aのギャップを「単一のレバー」で埋めるとどうなるか
A17: 協賛以外の収益（団体課金＋その他）の累計 | B17: =SUM(月次モデル!B33:G33)+SUM(月次モデル!B34:G34)
A18: 協賛で稼ぐ必要のある額 | B18: =B4-B17
A19: いまの見込み案件数（6ヶ月累計） | B19: =月次モデル!G29
A21: ① 案件数だけで埋める：必要な累計案件数 | B21: =B18/前提!$B$17 | C21: 単価・手数料率を据え置いた場合
A22: 必要倍率 | B22: =IF(B19=0,0,B21/B19) | C22: 1.5倍を超えると計画変更が要る
A23: ② 単価だけで埋める：必要な協賛平均金額 | B23: =IF(B19=0,0,B18/(B19*前提!$B$16)) | C23: 案件数を据え置いた場合
A24: 必要倍率 | B24: =IF(前提!$B$15=0,0,B23/前提!$B$15)
A25: ③ 手数料率だけで埋める：必要な手数料率 | B25: =IF(B19=0,0,B18/(B19*前提!$B$15)) | C25: 30%超は交渉上ほぼ通らない
A26: ④ 団体課金だけで埋める：必要な有料団体数 | B26: =IF(前提!$B$18=0,0,MAX(0,(B4-SUM(月次モデル!B32:G32))/(前提!$B$18*前提!$B$11))) | C26: 6ヶ月間ずっとこの数が課金している前提。0なら協賛だけで足りている
A28: ■ 判定
A29: 定義A（累計回収） | B29: =IF(B7>=前提!$B$37,"達成","未達") | C29: =IF(B7>=前提!$B$37,"この前提なら1月末に投資を回収できる","不足額 "&TEXT(B6,"¥#,##0")&"。上の①〜④のどれで埋めるかを決める")
A30: 定義B（月次ランレート黒字） | B30: =IF(B13>=1,"達成","未達") | C30: =IF(B13>=1,"1月時点で自走できる","1月に案件が "&TEXT(B14,"0.0")&" 件必要。いまの見込みは "&TEXT(月次モデル!G28,"0.0")&" 件")
A32: ※ 団体を増やしてもこのシートの数字はほぼ動かない。案件の律速が企業側だから。
A33: 回収を動かすのは ②協賛単価 と、企業打診の量である。

Sheet 稼働キャパ
A1: 稼働キャパ（週6時間×3名でその投下量は回るのか）
A3: ■ 使える時間
A4: 月次の稼働可能時間（3名合計） | B4: =前提!$B$4*前提!$B$6*前提!$B$7
A5: 期間合計（6ヶ月） | B5: =B4*前提!$B$11
A6: うちアウトリーチに充てられる時間 | B6: =B5*前提!$B$50 | C6: 残りは開発・SEO・管理
A8: ■ 必要な工数
A9: 掲載通知（SNS DM・サイトフォーム） | B9: =SUM(月次モデル!B13:G13)*前提!$B$45
A10: 登録団体のセルフサーブ支援 | B10: =月次モデル!G18*前提!$B$46
A11: 実運用化のハンズオン | B11: =SUM(月次モデル!B19:G19)*前提!$B$47
A12: 企業打診 | B12: =SUM(前提!B42:G42)*前提!$B$48
A13: 商談 | B13: =SUM(月次モデル!B25:G25)*前提!$B$49
A14: 必要工数 合計 | B14: =SUM(B9:B13)
A15: 余裕（アウトリーチ枠 − 必要工数） | B15: =B6-B14
A16: アウトリーチ枠の消化率 | B16: =IF(B6=0,0,B14/B6)
A17: 判定 | B17: =IF(B16<=1,"収まる","超過") | C17: =IF(B16<=1,"あと "&TEXT(B15,"0")&" 時間の余力がある","超過 "&TEXT(-B15,"0")&" 時間。投下量を減らすか、人員・稼働時間を増やす")
A19: ※ 100団体を狙うとき、最大の変数は「実運用化のハンズオン1団体あたり時間」（前提 B47）である。
A20: 3.0hのままだと消化率115%で破綻する。1.5h（＝セルフサーブ＋要点だけ支援）で92%に収まる。
A21: ※ 掲載通知は一斉自動送信ができない（メール列が無くSNS DM/サイトフォームのため）。1件2.4分は手作業前提の数字。

Sheet 感度分析
A1: 感度分析：累計案件数 × 協賛平均金額 → 累計回収率
A3: 縦＝協賛1案件の平均金額 ／ 横＝6ヶ月の累計案件数
A4: 手数料率と累計コストは「前提」シートの値を使う。緑＝回収達成（100%以上）。
B6: 案件数 → | C6: 2 | D6: 4 | E6: 6 | F6: 8 | G6: 10 | H6: 12 | I6: 14 | J6: 16 | K6: 18 | L6: 20
B7: 100000 | C7: =$B7*C$6*前提!$B$16/前提!$B$12 | D7: =$B7*D$6*前提!$B$16/前提!$B$12 | E7: =$B7*E$6*前提!$B$16/前提!$B$12 | F7: =$B7*F$6*前提!$B$16/前提!$B$12 | G7: =$B7*G$6*前提!$B$16/前提!$B$12 | H7: =$B7*H$6*前提!$B$16/前提!$B$12 | I7: =$B7*I$6*前提!$B$16/前提!$B$12 | J7: =$B7*J$6*前提!$B$16/前提!$B$12 | ... L7: =$B7*L$6*前提!$B$16/前提!$B$12
B8: 200000 | C8: =$B8*C$6*前提!$B$16/前提!$B$12 | D8: =$B8*D$6*前提!$B$16/前提!$B$12 | E8: =$B8*E$6*前提!$B$16/前提!$B$12 | F8: =$B8*F$6*前提!$B$16/前提!$B$12 | G8: =$B8*G$6*前提!$B$16/前提!$B$12 | H8: =$B8*H$6*前提!$B$16/前提!$B$12 | I8: =$B8*I$6*前提!$B$16/前提!$B$12 | J8: =$B8*J$6*前提!$B$16/前提!$B$12 | ... L8: =$B8*L$6*前提!$B$16/前提!$B$12
B9: 300000 | C9: =$B9*C$6*前提!$B$16/前提!$B$12 | D9: =$B9*D$6*前提!$B$16/前提!$B$12 | E9: =$B9*E$6*前提!$B$16/前提!$B$12 | F9: =$B9*F$6*前提!$B$16/前提!$B$12 | G9: =$B9*G$6*前提!$B$16/前提!$B$12 | H9: =$B9*H$6*前提!$B$16/前提!$B$12 | I9: =$B9*I$6*前提!$B$16/前提!$B$12 | J9: =$B9*J$6*前提!$B$16/前提!$B$12 | ... L9: =$B9*L$6*前提!$B$16/前提!$B$12
B10: 400000 | C10: =$B10*C$6*前提!$B$16/前提!$B$12 | D10: =$B10*D$6*前提!$B$16/前提!$B$12 | E10: =$B10*E$6*前提!$B$16/前提!$B$12 | F10: =$B10*F$6*前提!$B$16/前提!$B$12 | G10: =$B10*G$6*前提!$B$16/前提!$B$12 | H10: =$B10*H$6*前提!$B$16/前提!$B$12 | I10: =$B10*I$6*前提!$B$16/前提!$B$12 | J10: =$B10*J$6*前提!$B$16/前提!$B$12 | ... L10: =$B10*L$6*前提!$B$16/前提!$B$12
B11: 500000 | C11: =$B11*C$6*前提!$B$16/前提!$B$12 | D11: =$B11*D$6*前提!$B$16/前提!$B$12 | E11: =$B11*E$6*前提!$B$16/前提!$B$12 | F11: =$B11*F$6*前提!$B$16/前提!$B$12 | G11: =$B11*G$6*前提!$B$16/前提!$B$12 | H11: =$B11*H$6*前提!$B$16/前提!$B$12 | I11: =$B11*I$6*前提!$B$16/前提!$B$12 | J11: =$B11*J$6*前提!$B$16/前提!$B$12 | ... L11: =$B11*L$6*前提!$B$16/前提!$B$12
B12: 600000 | C12: =$B12*C$6*前提!$B$16/前提!$B$12 | D12: =$B12*D$6*前提!$B$16/前提!$B$12 | E12: =$B12*E$6*前提!$B$16/前提!$B$12 | F12: =$B12*F$6*前提!$B$16/前提!$B$12 | G12: =$B12*G$6*前提!$B$16/前提!$B$12 | H12: =$B12*H$6*前提!$B$16/前提!$B$12 | I12: =$B12*I$6*前提!$B$16/前提!$B$12 | J12: =$B12*J$6*前提!$B$16/前提!$B$12 | ... L12: =$B12*L$6*前提!$B$16/前提!$B$12
B13: 800000 | C13: =$B13*C$6*前提!$B$16/前提!$B$12 | D13: =$B13*D$6*前提!$B$16/前提!$B$12 | E13: =$B13*E$6*前提!$B$16/前提!$B$12 | F13: =$B13*F$6*前提!$B$16/前提!$B$12 | G13: =$B13*G$6*前提!$B$16/前提!$B$12 | H13: =$B13*H$6*前提!$B$16/前提!$B$12 | I13: =$B13*I$6*前提!$B$16/前提!$B$12 | J13: =$B13*J$6*前提!$B$16/前提!$B$12 | ... L13: =$B13*L$6*前提!$B$16/前提!$B$12
B14: 1000000 | C14: =$B14*C$6*前提!$B$16/前提!$B$12 | D14: =$B14*D$6*前提!$B$16/前提!$B$12 | E14: =$B14*E$6*前提!$B$16/前提!$B$12 | F14: =$B14*F$6*前提!$B$16/前提!$B$12 | G14: =$B14*G$6*前提!$B$16/前提!$B$12 | H14: =$B14*H$6*前提!$B$16/前提!$B$12 | I14: =$B14*I$6*前提!$B$16/前提!$B$12 | J14: =$B14*J$6*前提!$B$16/前提!$B$12 | ... L14: =$B14*L$6*前提!$B$16/前提!$B$12
A17: ※ 協賛手数料のみで計算している（団体課金・その他収益は含まない）。
A18: 緑のマスに入る組み合わせが、1月末に投資を回収できる条件。
